[2020-08-10 14:24:56,312] [autoreload.py:598] [autoreload:run_with_reloader] [INFO]- Watching for file changes with StatReloader
[2020-08-10 14:25:07,158] [basehttp.py:157] [basehttp:log_message] [INFO]- "GET / HTTP/1.1" 200 12086
[2020-08-10 14:25:07,174] [basehttp.py:157] [basehttp:log_message] [INFO]- "GET /static/login/js/echarts.min.js HTTP/1.1" 304 0
[2020-08-10 14:25:09,768] [log.py:228] [log:log_response] [WARNING]- Not Found: /favicon.ico
[2020-08-10 14:25:09,769] [basehttp.py:157] [basehttp:log_message] [WARNING]- "GET /favicon.ico HTTP/1.1" 404 179
[2020-08-10 14:25:13,047] [basehttp.py:157] [basehttp:log_message] [INFO]- "GET /platform/settlement_not_vip HTTP/1.1" 200 3506
[2020-08-10 14:25:13,070] [basehttp.py:157] [basehttp:log_message] [INFO]- "GET /static/login/css/send_vip.css HTTP/1.1" 304 0
[2020-08-10 14:33:35,603] [basehttp.py:157] [basehttp:log_message] [INFO]- "GET / HTTP/1.1" 200 12086
[2020-08-10 14:34:07,847] [autoreload.py:598] [autoreload:run_with_reloader] [INFO]- Watching for file changes with StatReloader
[2020-08-10 14:53:25,453] [autoreload.py:222] [autoreload:trigger_reload] [INFO]- E:\Auto\testplat\MyPro1\settings.py changed, reloading.
[2020-08-10 14:53:26,540] [autoreload.py:598] [autoreload:run_with_reloader] [INFO]- Watching for file changes with StatReloader
[2020-08-10 14:56:02,847] [autoreload.py:222] [autoreload:trigger_reload] [INFO]- E:\Auto\testplat\MyPro1\settings.py changed, reloading.
[2020-08-10 14:56:03,917] [autoreload.py:598] [autoreload:run_with_reloader] [INFO]- Watching for file changes with StatReloader
[2020-08-10 14:56:05,885] [autoreload.py:222] [autoreload:trigger_reload] [INFO]- E:\Auto\testplat\MyPro1\settings.py changed, reloading.
[2020-08-10 14:56:07,071] [autoreload.py:598] [autoreload:run_with_reloader] [INFO]- Watching for file changes with StatReloader
[2020-08-10 14:59:50,234] [basehttp.py:157] [basehttp:log_message] [INFO]- "GET /run_test/ HTTP/1.1" 200 3101
[2020-08-10 14:59:50,246] [basehttp.py:157] [basehttp:log_message] [INFO]- "GET /static/login/css/run_test.css HTTP/1.1" 304 0
[2020-08-10 15:03:19,374] [autotest_view.py:103] [autotest_view:run_test] [INFO]- 测试完成！ 测试结果集合为:{'filename': 'test_report20200810150237', 'result': {'testAll': 46, 'testPass': 37, 'testFail': 9, 'testError': 0}}
[2020-08-10 15:03:21,035] [basehttp.py:157] [basehttp:log_message] [INFO]- "GET /run_test/?csrfmiddlewaretoken=1NqntoJWnoI4n8LZ9XyesI4qtkcAO6aCCg5G9uOGzhSeJMAl7ojHSJhRTGByztwE&test_type=All&envId=3&project=yyting-apps-admin HTTP/1.1" 200 101
[2020-08-10 16:31:08,950] [basehttp.py:157] [basehttp:log_message] [INFO]- "GET / HTTP/1.1" 200 12086
[2020-08-10 16:31:14,601] [basehttp.py:157] [basehttp:log_message] [INFO]- "GET /add_cases/ HTTP/1.1" 200 3136
[2020-08-10 16:31:47,878] [log.py:228] [log:log_response] [ERROR]- Internal Server Error: /add_cases/
Traceback (most recent call last):
  File "C:\Users\dell\AppData\Local\Programs\Python\Python37\lib\site-packages\django\db\backends\utils.py", line 86, in _execute
    return self.cursor.execute(sql, params)
  File "C:\Users\dell\AppData\Local\Programs\Python\Python37\lib\site-packages\django\db\backends\mysql\base.py", line 74, in execute
    return self.cursor.execute(query, args)
  File "C:\Users\dell\AppData\Local\Programs\Python\Python37\lib\site-packages\pymysql\cursors.py", line 163, in execute
    result = self._query(query)
  File "C:\Users\dell\AppData\Local\Programs\Python\Python37\lib\site-packages\pymysql\cursors.py", line 321, in _query
    conn.query(q)
  File "C:\Users\dell\AppData\Local\Programs\Python\Python37\lib\site-packages\pymysql\connections.py", line 505, in query
    self._affected_rows = self._read_query_result(unbuffered=unbuffered)
  File "C:\Users\dell\AppData\Local\Programs\Python\Python37\lib\site-packages\pymysql\connections.py", line 724, in _read_query_result
    result.read()
  File "C:\Users\dell\AppData\Local\Programs\Python\Python37\lib\site-packages\pymysql\connections.py", line 1069, in read
    first_packet = self.connection._read_packet()
  File "C:\Users\dell\AppData\Local\Programs\Python\Python37\lib\site-packages\pymysql\connections.py", line 676, in _read_packet
    packet.raise_for_error()
  File "C:\Users\dell\AppData\Local\Programs\Python\Python37\lib\site-packages\pymysql\protocol.py", line 223, in raise_for_error
    err.raise_mysql_exception(self._data)
  File "C:\Users\dell\AppData\Local\Programs\Python\Python37\lib\site-packages\pymysql\err.py", line 107, in raise_mysql_exception
    raise errorclass(errno, errval)
pymysql.err.IntegrityError: (1048, "Column 'case_creater' cannot be null")

The above exception was the direct cause of the following exception:

Traceback (most recent call last):
  File "C:\Users\dell\AppData\Local\Programs\Python\Python37\lib\site-packages\django\core\handlers\exception.py", line 34, in inner
    response = get_response(request)
  File "C:\Users\dell\AppData\Local\Programs\Python\Python37\lib\site-packages\django\core\handlers\base.py", line 115, in _get_response
    response = self.process_exception_by_middleware(e, request)
  File "C:\Users\dell\AppData\Local\Programs\Python\Python37\lib\site-packages\django\core\handlers\base.py", line 113, in _get_response
    response = wrapped_callback(request, *callback_args, **callback_kwargs)
  File "E:\Auto\testplat\login\viewas\test_view\cases_views.py", line 141, in add_cases
    cases.save()
  File "C:\Users\dell\AppData\Local\Programs\Python\Python37\lib\site-packages\django\db\models\base.py", line 746, in save
    force_update=force_update, update_fields=update_fields)
  File "C:\Users\dell\AppData\Local\Programs\Python\Python37\lib\site-packages\django\db\models\base.py", line 784, in save_base
    force_update, using, update_fields,
  File "C:\Users\dell\AppData\Local\Programs\Python\Python37\lib\site-packages\django\db\models\base.py", line 887, in _save_table
    results = self._do_insert(cls._base_manager, using, fields, returning_fields, raw)
  File "C:\Users\dell\AppData\Local\Programs\Python\Python37\lib\site-packages\django\db\models\base.py", line 926, in _do_insert
    using=using, raw=raw,
  File "C:\Users\dell\AppData\Local\Programs\Python\Python37\lib\site-packages\django\db\models\manager.py", line 82, in manager_method
    return getattr(self.get_queryset(), name)(*args, **kwargs)
  File "C:\Users\dell\AppData\Local\Programs\Python\Python37\lib\site-packages\django\db\models\query.py", line 1204, in _insert
    return query.get_compiler(using=using).execute_sql(returning_fields)
  File "C:\Users\dell\AppData\Local\Programs\Python\Python37\lib\site-packages\django\db\models\sql\compiler.py", line 1392, in execute_sql
    cursor.execute(sql, params)
  File "C:\Users\dell\AppData\Local\Programs\Python\Python37\lib\site-packages\django\db\backends\utils.py", line 68, in execute
    return self._execute_with_wrappers(sql, params, many=False, executor=self._execute)
  File "C:\Users\dell\AppData\Local\Programs\Python\Python37\lib\site-packages\django\db\backends\utils.py", line 77, in _execute_with_wrappers
    return executor(sql, params, many, context)
  File "C:\Users\dell\AppData\Local\Programs\Python\Python37\lib\site-packages\django\db\backends\utils.py", line 86, in _execute
    return self.cursor.execute(sql, params)
  File "C:\Users\dell\AppData\Local\Programs\Python\Python37\lib\site-packages\django\db\utils.py", line 90, in __exit__
    raise dj_exc_value.with_traceback(traceback) from exc_value
  File "C:\Users\dell\AppData\Local\Programs\Python\Python37\lib\site-packages\django\db\backends\utils.py", line 86, in _execute
    return self.cursor.execute(sql, params)
  File "C:\Users\dell\AppData\Local\Programs\Python\Python37\lib\site-packages\django\db\backends\mysql\base.py", line 74, in execute
    return self.cursor.execute(query, args)
  File "C:\Users\dell\AppData\Local\Programs\Python\Python37\lib\site-packages\pymysql\cursors.py", line 163, in execute
    result = self._query(query)
  File "C:\Users\dell\AppData\Local\Programs\Python\Python37\lib\site-packages\pymysql\cursors.py", line 321, in _query
    conn.query(q)
  File "C:\Users\dell\AppData\Local\Programs\Python\Python37\lib\site-packages\pymysql\connections.py", line 505, in query
    self._affected_rows = self._read_query_result(unbuffered=unbuffered)
  File "C:\Users\dell\AppData\Local\Programs\Python\Python37\lib\site-packages\pymysql\connections.py", line 724, in _read_query_result
    result.read()
  File "C:\Users\dell\AppData\Local\Programs\Python\Python37\lib\site-packages\pymysql\connections.py", line 1069, in read
    first_packet = self.connection._read_packet()
  File "C:\Users\dell\AppData\Local\Programs\Python\Python37\lib\site-packages\pymysql\connections.py", line 676, in _read_packet
    packet.raise_for_error()
  File "C:\Users\dell\AppData\Local\Programs\Python\Python37\lib\site-packages\pymysql\protocol.py", line 223, in raise_for_error
    err.raise_mysql_exception(self._data)
  File "C:\Users\dell\AppData\Local\Programs\Python\Python37\lib\site-packages\pymysql\err.py", line 107, in raise_mysql_exception
    raise errorclass(errno, errval)
django.db.utils.IntegrityError: (1048, "Column 'case_creater' cannot be null")
[2020-08-10 16:31:47,888] [basehttp.py:157] [basehttp:log_message] [ERROR]- "POST /add_cases/ HTTP/1.1" 500 145
[2020-08-10 16:32:22,962] [basehttp.py:157] [basehttp:log_message] [INFO]- "GET / HTTP/1.1" 200 12086
[2020-08-10 16:32:24,371] [basehttp.py:157] [basehttp:log_message] [INFO]- "GET /login/ HTTP/1.1" 200 2210
[2020-08-10 16:32:24,401] [basehttp.py:157] [basehttp:log_message] [INFO]- "GET /static/login/css/login.css HTTP/1.1" 304 0
[2020-08-10 16:32:24,415] [basehttp.py:157] [basehttp:log_message] [INFO]- "GET /static/login/img/photos/timg3.jpg HTTP/1.1" 304 0
[2020-08-10 16:32:32,467] [basehttp.py:157] [basehttp:log_message] [INFO]- "POST /login/ HTTP/1.1" 302 0
[2020-08-10 16:32:32,484] [basehttp.py:157] [basehttp:log_message] [INFO]- "GET / HTTP/1.1" 200 12094
[2020-08-10 16:32:34,075] [basehttp.py:157] [basehttp:log_message] [INFO]- "GET /add_cases/ HTTP/1.1" 200 3136
[2020-08-10 16:33:03,844] [basehttp.py:157] [basehttp:log_message] [INFO]- "POST /add_cases/ HTTP/1.1" 200 3283
[2020-08-10 16:33:05,087] [basehttp.py:157] [basehttp:log_message] [INFO]- "POST /add_cases/ HTTP/1.1" 200 3389
[2020-08-10 16:33:08,521] [basehttp.py:157] [basehttp:log_message] [INFO]- "GET /cases_detail/ HTTP/1.1" 200 45225
[2020-08-10 16:33:29,672] [basehttp.py:157] [basehttp:log_message] [INFO]- "GET /delete_case/?delete_id=42 HTTP/1.1" 302 0
[2020-08-10 16:33:29,695] [basehttp.py:157] [basehttp:log_message] [INFO]- "GET /cases_pages/1 HTTP/1.1" 200 16461
[2020-08-10 16:33:33,184] [basehttp.py:157] [basehttp:log_message] [INFO]- "GET /cases_pages/3 HTTP/1.1" 200 12956
[2020-08-10 16:33:37,398] [basehttp.py:157] [basehttp:log_message] [INFO]- "GET /run_case/?run_id=43 HTTP/1.1" 200 54
[2020-08-10 16:33:55,864] [basehttp.py:157] [basehttp:log_message] [INFO]- "GET /case_edit/?edit_id=43 HTTP/1.1" 200 2397
[2020-08-10 16:34:04,734] [basehttp.py:157] [basehttp:log_message] [INFO]- "GET /run_case/?run_id=43 HTTP/1.1" 200 54
[2020-08-10 16:34:28,294] [basehttp.py:157] [basehttp:log_message] [INFO]- "GET / HTTP/1.1" 200 12094
[2020-08-10 16:34:30,307] [basehttp.py:157] [basehttp:log_message] [INFO]- "GET /add_cases/ HTTP/1.1" 200 3136
[2020-08-10 16:34:32,419] [basehttp.py:157] [basehttp:log_message] [INFO]- "GET /cases_pages/1 HTTP/1.1" 200 16461
[2020-08-10 16:34:35,121] [basehttp.py:157] [basehttp:log_message] [INFO]- "GET /cases_pages/3 HTTP/1.1" 200 12956
[2020-08-10 16:34:36,511] [basehttp.py:157] [basehttp:log_message] [INFO]- "GET /run_case/?run_id=43 HTTP/1.1" 200 54
[2020-08-10 16:37:59,531] [basehttp.py:157] [basehttp:log_message] [INFO]- "GET /run_case/?run_id=31 HTTP/1.1" 302 0
[2020-08-10 16:37:59,552] [basehttp.py:157] [basehttp:log_message] [INFO]- "GET /cases_pages/1 HTTP/1.1" 200 16461
[2020-08-10 16:38:11,733] [basehttp.py:157] [basehttp:log_message] [INFO]- "GET /run_case/?run_id=15 HTTP/1.1" 302 0
[2020-08-10 16:38:11,753] [basehttp.py:157] [basehttp:log_message] [INFO]- "GET /cases_pages/1 HTTP/1.1" 200 16461
[2020-08-10 16:38:14,356] [basehttp.py:157] [basehttp:log_message] [INFO]- "GET / HTTP/1.1" 200 12094
[2020-08-10 16:38:21,284] [basehttp.py:157] [basehttp:log_message] [INFO]- "GET /cases_pages/1 HTTP/1.1" 200 16461
[2020-08-10 16:38:23,273] [basehttp.py:157] [basehttp:log_message] [INFO]- "GET /cases_pages/3 HTTP/1.1" 200 12956
[2020-08-10 16:42:26,407] [basehttp.py:157] [basehttp:log_message] [INFO]- "GET /run_case/?run_id=43 HTTP/1.1" 200 54
[2020-08-10 16:42:46,405] [autoreload.py:598] [autoreload:run_with_reloader] [INFO]- Watching for file changes with StatReloader
[2020-08-10 16:42:51,978] [basehttp.py:157] [basehttp:log_message] [INFO]- "GET /run_case/?run_id=43 HTTP/1.1" 200 54
[2020-08-10 16:43:41,542] [basehttp.py:157] [basehttp:log_message] [INFO]- "GET /cases_pages/1 HTTP/1.1" 200 16461
[2020-08-10 16:43:44,192] [basehttp.py:157] [basehttp:log_message] [INFO]- "GET /cases_pages/1 HTTP/1.1" 200 16461
[2020-08-10 16:43:46,498] [basehttp.py:157] [basehttp:log_message] [INFO]- "GET /cases_pages/2 HTTP/1.1" 200 15507
[2020-08-10 16:43:49,273] [basehttp.py:157] [basehttp:log_message] [INFO]- "GET /cases_pages/2 HTTP/1.1" 200 15507
[2020-08-10 16:43:51,320] [basehttp.py:157] [basehttp:log_message] [INFO]- "GET /cases_pages/3 HTTP/1.1" 200 12956
[2020-08-10 16:53:34,764] [autoreload.py:598] [autoreload:run_with_reloader] [INFO]- Watching for file changes with StatReloader
[2020-08-10 16:53:47,409] [basehttp.py:157] [basehttp:log_message] [INFO]- "GET /run_case/?run_id=43 HTTP/1.1" 200 54
[2020-08-10 17:10:38,698] [autoreload.py:222] [autoreload:trigger_reload] [INFO]- E:\Auto\testplat\login\forms.py changed, reloading.
[2020-08-10 17:10:39,787] [autoreload.py:598] [autoreload:run_with_reloader] [INFO]- Watching for file changes with StatReloader
[2020-08-10 17:10:55,816] [autoreload.py:222] [autoreload:trigger_reload] [INFO]- E:\Auto\testplat\login\forms.py changed, reloading.
[2020-08-10 17:10:56,890] [autoreload.py:598] [autoreload:run_with_reloader] [INFO]- Watching for file changes with StatReloader
[2020-08-10 17:20:33,010] [basehttp.py:157] [basehttp:log_message] [INFO]- "GET / HTTP/1.1" 200 12089
[2020-08-10 17:20:33,082] [basehttp.py:157] [basehttp:log_message] [INFO]- "GET /static/login/js/echarts.min.js HTTP/1.1" 304 0
[2020-08-10 17:20:33,256] [log.py:228] [log:log_response] [WARNING]- Not Found: /favicon.ico
[2020-08-10 17:20:33,257] [basehttp.py:157] [basehttp:log_message] [WARNING]- "GET /favicon.ico HTTP/1.1" 404 179
[2020-08-10 17:20:40,020] [autoreload.py:598] [autoreload:run_with_reloader] [INFO]- Watching for file changes with StatReloader
[2020-08-10 17:20:54,699] [log.py:228] [log:log_response] [WARNING]- Not Found: /run_case
[2020-08-10 17:20:54,700] [basehttp.py:157] [basehttp:log_message] [WARNING]- "GET /run_case HTTP/1.1" 404 179
[2020-08-10 17:20:58,100] [basehttp.py:157] [basehttp:log_message] [INFO]- "GET / HTTP/1.1" 200 12094
[2020-08-10 17:21:03,597] [basehttp.py:157] [basehttp:log_message] [INFO]- "GET /run_test/ HTTP/1.1" 200 3285
[2020-08-10 17:23:20,423] [autotest_view.py:103] [autotest_view:run_test] [INFO]- 测试完成！ 测试结果集合为:{'filename': 'test_report20200810172203', 'result': {'testAll': 47, 'testPass': 37, 'testFail': 10, 'testError': 0}}
[2020-08-10 17:23:20,516] [basehttp.py:157] [basehttp:log_message] [INFO]- "GET /run_test/?csrfmiddlewaretoken=FaOVKVHPxlvyDJ1fPO3N0hDNLl8lVCN0gDteq1MzJeFIZnQBNfOgqiQebHxjGZ92&test_type=All&envId=3&project=platform-billing-admin HTTP/1.1" 200 106
[2020-08-10 17:24:00,737] [basehttp.py:157] [basehttp:log_message] [INFO]- "GET /test_report_list10/ HTTP/1.1" 200 12387
[2020-08-10 17:24:00,962] [basehttp.py:157] [basehttp:log_message] [INFO]- "GET /api/pass_stats/ HTTP/1.1" 200 106
[2020-08-10 17:24:00,968] [basehttp.py:157] [basehttp:log_message] [INFO]- "GET /api/echarts/ HTTP/1.1" 200 80
[2020-08-10 17:24:06,572] [basehttp.py:157] [basehttp:log_message] [INFO]- "GET /test_report/test_report20200810172203 HTTP/1.1" 200 15397166
[2020-08-10 17:31:54,139] [autoreload.py:598] [autoreload:run_with_reloader] [INFO]- Watching for file changes with StatReloader
[2020-08-10 17:33:12,764] [autoreload.py:222] [autoreload:trigger_reload] [INFO]- E:\Auto\testplat\MyPro1\settings.py changed, reloading.
[2020-08-10 17:33:13,862] [autoreload.py:598] [autoreload:run_with_reloader] [INFO]- Watching for file changes with StatReloader
[2020-08-10 17:37:00,934] [basehttp.py:157] [basehttp:log_message] [INFO]- "GET / HTTP/1.1" 200 12086
[2020-08-10 17:37:02,599] [basehttp.py:157] [basehttp:log_message] [INFO]- "GET / HTTP/1.1" 200 12086
[2020-08-10 17:37:05,180] [basehttp.py:157] [basehttp:log_message] [INFO]- "GET /run_test/ HTTP/1.1" 200 3285
[2020-08-10 17:38:06,402] [autotest_view.py:103] [autotest_view:run_test] [INFO]- 测试完成！ 测试结果集合为:{'filename': 'test_report20200810173710', 'result': {'testAll': 47, 'testPass': 38, 'testFail': 9, 'testError': 0}}
[2020-08-10 17:38:07,598] [basehttp.py:157] [basehttp:log_message] [INFO]- "GET /run_test/?csrfmiddlewaretoken=vbPyKm9IwctHglR6wAlHucXa228nbs6U6EuRqsesI5DRCZGsu16aUdaBsoxlWPsW&test_type=All&envId=3&project=platform-billing-admin HTTP/1.1" 200 106
[2020-08-10 17:38:19,198] [log.py:228] [log:log_response] [ERROR]- Internal Server Error: /test_report_list10/
Traceback (most recent call last):
  File "C:\Users\dell\AppData\Local\Programs\Python\Python37\lib\site-packages\django\db\backends\utils.py", line 86, in _execute
    return self.cursor.execute(sql, params)
  File "C:\Users\dell\AppData\Local\Programs\Python\Python37\lib\site-packages\django\db\backends\mysql\base.py", line 74, in execute
    return self.cursor.execute(query, args)
  File "C:\Users\dell\AppData\Local\Programs\Python\Python37\lib\site-packages\pymysql\cursors.py", line 163, in execute
    result = self._query(query)
  File "C:\Users\dell\AppData\Local\Programs\Python\Python37\lib\site-packages\pymysql\cursors.py", line 321, in _query
    conn.query(q)
  File "C:\Users\dell\AppData\Local\Programs\Python\Python37\lib\site-packages\pymysql\connections.py", line 505, in query
    self._affected_rows = self._read_query_result(unbuffered=unbuffered)
  File "C:\Users\dell\AppData\Local\Programs\Python\Python37\lib\site-packages\pymysql\connections.py", line 724, in _read_query_result
    result.read()
  File "C:\Users\dell\AppData\Local\Programs\Python\Python37\lib\site-packages\pymysql\connections.py", line 1069, in read
    first_packet = self.connection._read_packet()
  File "C:\Users\dell\AppData\Local\Programs\Python\Python37\lib\site-packages\pymysql\connections.py", line 676, in _read_packet
    packet.raise_for_error()
  File "C:\Users\dell\AppData\Local\Programs\Python\Python37\lib\site-packages\pymysql\protocol.py", line 223, in raise_for_error
    err.raise_mysql_exception(self._data)
  File "C:\Users\dell\AppData\Local\Programs\Python\Python37\lib\site-packages\pymysql\err.py", line 107, in raise_mysql_exception
    raise errorclass(errno, errval)
pymysql.err.OperationalError: (1054, "Unknown column 'login_settlement_not_vip_models.settlement_month' in 'field list'")

The above exception was the direct cause of the following exception:

Traceback (most recent call last):
  File "C:\Users\dell\AppData\Local\Programs\Python\Python37\lib\site-packages\django\core\handlers\exception.py", line 34, in inner
    response = get_response(request)
  File "C:\Users\dell\AppData\Local\Programs\Python\Python37\lib\site-packages\django\core\handlers\base.py", line 115, in _get_response
    response = self.process_exception_by_middleware(e, request)
  File "C:\Users\dell\AppData\Local\Programs\Python\Python37\lib\site-packages\django\core\handlers\base.py", line 113, in _get_response
    response = wrapped_callback(request, *callback_args, **callback_kwargs)
  File "E:\Auto\testplat\login\viewas\test_view\autotest_view.py", line 203, in test_report_list10
    print('结算结果：', settlement_data)
  File "C:\Users\dell\AppData\Local\Programs\Python\Python37\lib\site-packages\django\db\models\query.py", line 252, in __repr__
    data = list(self[:REPR_OUTPUT_SIZE + 1])
  File "C:\Users\dell\AppData\Local\Programs\Python\Python37\lib\site-packages\django\db\models\query.py", line 276, in __iter__
    self._fetch_all()
  File "C:\Users\dell\AppData\Local\Programs\Python\Python37\lib\site-packages\django\db\models\query.py", line 1261, in _fetch_all
    self._result_cache = list(self._iterable_class(self))
  File "C:\Users\dell\AppData\Local\Programs\Python\Python37\lib\site-packages\django\db\models\query.py", line 115, in __iter__
    for row in compiler.results_iter(chunked_fetch=self.chunked_fetch, chunk_size=self.chunk_size):
  File "C:\Users\dell\AppData\Local\Programs\Python\Python37\lib\site-packages\django\db\models\sql\compiler.py", line 1104, in results_iter
    results = self.execute_sql(MULTI, chunked_fetch=chunked_fetch, chunk_size=chunk_size)
  File "C:\Users\dell\AppData\Local\Programs\Python\Python37\lib\site-packages\django\db\models\sql\compiler.py", line 1152, in execute_sql
    cursor.execute(sql, params)
  File "C:\Users\dell\AppData\Local\Programs\Python\Python37\lib\site-packages\django\db\backends\utils.py", line 68, in execute
    return self._execute_with_wrappers(sql, params, many=False, executor=self._execute)
  File "C:\Users\dell\AppData\Local\Programs\Python\Python37\lib\site-packages\django\db\backends\utils.py", line 77, in _execute_with_wrappers
    return executor(sql, params, many, context)
  File "C:\Users\dell\AppData\Local\Programs\Python\Python37\lib\site-packages\django\db\backends\utils.py", line 86, in _execute
    return self.cursor.execute(sql, params)
  File "C:\Users\dell\AppData\Local\Programs\Python\Python37\lib\site-packages\django\db\utils.py", line 90, in __exit__
    raise dj_exc_value.with_traceback(traceback) from exc_value
  File "C:\Users\dell\AppData\Local\Programs\Python\Python37\lib\site-packages\django\db\backends\utils.py", line 86, in _execute
    return self.cursor.execute(sql, params)
  File "C:\Users\dell\AppData\Local\Programs\Python\Python37\lib\site-packages\django\db\backends\mysql\base.py", line 74, in execute
    return self.cursor.execute(query, args)
  File "C:\Users\dell\AppData\Local\Programs\Python\Python37\lib\site-packages\pymysql\cursors.py", line 163, in execute
    result = self._query(query)
  File "C:\Users\dell\AppData\Local\Programs\Python\Python37\lib\site-packages\pymysql\cursors.py", line 321, in _query
    conn.query(q)
  File "C:\Users\dell\AppData\Local\Programs\Python\Python37\lib\site-packages\pymysql\connections.py", line 505, in query
    self._affected_rows = self._read_query_result(unbuffered=unbuffered)
  File "C:\Users\dell\AppData\Local\Programs\Python\Python37\lib\site-packages\pymysql\connections.py", line 724, in _read_query_result
    result.read()
  File "C:\Users\dell\AppData\Local\Programs\Python\Python37\lib\site-packages\pymysql\connections.py", line 1069, in read
    first_packet = self.connection._read_packet()
  File "C:\Users\dell\AppData\Local\Programs\Python\Python37\lib\site-packages\pymysql\connections.py", line 676, in _read_packet
    packet.raise_for_error()
  File "C:\Users\dell\AppData\Local\Programs\Python\Python37\lib\site-packages\pymysql\protocol.py", line 223, in raise_for_error
    err.raise_mysql_exception(self._data)
  File "C:\Users\dell\AppData\Local\Programs\Python\Python37\lib\site-packages\pymysql\err.py", line 107, in raise_mysql_exception
    raise errorclass(errno, errval)
django.db.utils.OperationalError: (1054, "Unknown column 'login_settlement_not_vip_models.settlement_month' in 'field list'")
[2020-08-10 17:38:19,202] [basehttp.py:157] [basehttp:log_message] [ERROR]- "GET /test_report_list10/ HTTP/1.1" 500 145
[2020-08-10 17:43:42,594] [autoreload.py:598] [autoreload:run_with_reloader] [INFO]- Watching for file changes with StatReloader
[2020-08-10 17:45:37,091] [basehttp.py:157] [basehttp:log_message] [INFO]- "GET /platform/settlement_not_vip HTTP/1.1" 200 3506
[2020-08-10 17:45:39,746] [log.py:228] [log:log_response] [ERROR]- Internal Server Error: /platform/settlement_not_vip_result
Traceback (most recent call last):
  File "C:\Users\dell\AppData\Local\Programs\Python\Python37\lib\site-packages\django\db\backends\utils.py", line 86, in _execute
    return self.cursor.execute(sql, params)
  File "C:\Users\dell\AppData\Local\Programs\Python\Python37\lib\site-packages\django\db\backends\mysql\base.py", line 74, in execute
    return self.cursor.execute(query, args)
  File "C:\Users\dell\AppData\Local\Programs\Python\Python37\lib\site-packages\pymysql\cursors.py", line 163, in execute
    result = self._query(query)
  File "C:\Users\dell\AppData\Local\Programs\Python\Python37\lib\site-packages\pymysql\cursors.py", line 321, in _query
    conn.query(q)
  File "C:\Users\dell\AppData\Local\Programs\Python\Python37\lib\site-packages\pymysql\connections.py", line 505, in query
    self._affected_rows = self._read_query_result(unbuffered=unbuffered)
  File "C:\Users\dell\AppData\Local\Programs\Python\Python37\lib\site-packages\pymysql\connections.py", line 724, in _read_query_result
    result.read()
  File "C:\Users\dell\AppData\Local\Programs\Python\Python37\lib\site-packages\pymysql\connections.py", line 1069, in read
    first_packet = self.connection._read_packet()
  File "C:\Users\dell\AppData\Local\Programs\Python\Python37\lib\site-packages\pymysql\connections.py", line 676, in _read_packet
    packet.raise_for_error()
  File "C:\Users\dell\AppData\Local\Programs\Python\Python37\lib\site-packages\pymysql\protocol.py", line 223, in raise_for_error
    err.raise_mysql_exception(self._data)
  File "C:\Users\dell\AppData\Local\Programs\Python\Python37\lib\site-packages\pymysql\err.py", line 107, in raise_mysql_exception
    raise errorclass(errno, errval)
pymysql.err.OperationalError: (1054, "Unknown column 'login_settlement_not_vip_models.settlement_month' in 'field list'")

The above exception was the direct cause of the following exception:

Traceback (most recent call last):
  File "C:\Users\dell\AppData\Local\Programs\Python\Python37\lib\site-packages\django\core\handlers\exception.py", line 34, in inner
    response = get_response(request)
  File "C:\Users\dell\AppData\Local\Programs\Python\Python37\lib\site-packages\django\core\handlers\base.py", line 115, in _get_response
    response = self.process_exception_by_middleware(e, request)
  File "C:\Users\dell\AppData\Local\Programs\Python\Python37\lib\site-packages\django\core\handlers\base.py", line 113, in _get_response
    response = wrapped_callback(request, *callback_args, **callback_kwargs)
  File "E:\Auto\testplat\login\viewas\platform_views\settlement_views.py", line 66, in settlement_not_vip_result
    print('结算结果：', settlement_data)
  File "C:\Users\dell\AppData\Local\Programs\Python\Python37\lib\site-packages\django\db\models\query.py", line 252, in __repr__
    data = list(self[:REPR_OUTPUT_SIZE + 1])
  File "C:\Users\dell\AppData\Local\Programs\Python\Python37\lib\site-packages\django\db\models\query.py", line 276, in __iter__
    self._fetch_all()
  File "C:\Users\dell\AppData\Local\Programs\Python\Python37\lib\site-packages\django\db\models\query.py", line 1261, in _fetch_all
    self._result_cache = list(self._iterable_class(self))
  File "C:\Users\dell\AppData\Local\Programs\Python\Python37\lib\site-packages\django\db\models\query.py", line 115, in __iter__
    for row in compiler.results_iter(chunked_fetch=self.chunked_fetch, chunk_size=self.chunk_size):
  File "C:\Users\dell\AppData\Local\Programs\Python\Python37\lib\site-packages\django\db\models\sql\compiler.py", line 1104, in results_iter
    results = self.execute_sql(MULTI, chunked_fetch=chunked_fetch, chunk_size=chunk_size)
  File "C:\Users\dell\AppData\Local\Programs\Python\Python37\lib\site-packages\django\db\models\sql\compiler.py", line 1152, in execute_sql
    cursor.execute(sql, params)
  File "C:\Users\dell\AppData\Local\Programs\Python\Python37\lib\site-packages\django\db\backends\utils.py", line 68, in execute
    return self._execute_with_wrappers(sql, params, many=False, executor=self._execute)
  File "C:\Users\dell\AppData\Local\Programs\Python\Python37\lib\site-packages\django\db\backends\utils.py", line 77, in _execute_with_wrappers
    return executor(sql, params, many, context)
  File "C:\Users\dell\AppData\Local\Programs\Python\Python37\lib\site-packages\django\db\backends\utils.py", line 86, in _execute
    return self.cursor.execute(sql, params)
  File "C:\Users\dell\AppData\Local\Programs\Python\Python37\lib\site-packages\django\db\utils.py", line 90, in __exit__
    raise dj_exc_value.with_traceback(traceback) from exc_value
  File "C:\Users\dell\AppData\Local\Programs\Python\Python37\lib\site-packages\django\db\backends\utils.py", line 86, in _execute
    return self.cursor.execute(sql, params)
  File "C:\Users\dell\AppData\Local\Programs\Python\Python37\lib\site-packages\django\db\backends\mysql\base.py", line 74, in execute
    return self.cursor.execute(query, args)
  File "C:\Users\dell\AppData\Local\Programs\Python\Python37\lib\site-packages\pymysql\cursors.py", line 163, in execute
    result = self._query(query)
  File "C:\Users\dell\AppData\Local\Programs\Python\Python37\lib\site-packages\pymysql\cursors.py", line 321, in _query
    conn.query(q)
  File "C:\Users\dell\AppData\Local\Programs\Python\Python37\lib\site-packages\pymysql\connections.py", line 505, in query
    self._affected_rows = self._read_query_result(unbuffered=unbuffered)
  File "C:\Users\dell\AppData\Local\Programs\Python\Python37\lib\site-packages\pymysql\connections.py", line 724, in _read_query_result
    result.read()
  File "C:\Users\dell\AppData\Local\Programs\Python\Python37\lib\site-packages\pymysql\connections.py", line 1069, in read
    first_packet = self.connection._read_packet()
  File "C:\Users\dell\AppData\Local\Programs\Python\Python37\lib\site-packages\pymysql\connections.py", line 676, in _read_packet
    packet.raise_for_error()
  File "C:\Users\dell\AppData\Local\Programs\Python\Python37\lib\site-packages\pymysql\protocol.py", line 223, in raise_for_error
    err.raise_mysql_exception(self._data)
  File "C:\Users\dell\AppData\Local\Programs\Python\Python37\lib\site-packages\pymysql\err.py", line 107, in raise_mysql_exception
    raise errorclass(errno, errval)
django.db.utils.OperationalError: (1054, "Unknown column 'login_settlement_not_vip_models.settlement_month' in 'field list'")
[2020-08-10 17:45:39,751] [basehttp.py:157] [basehttp:log_message] [ERROR]- "GET /platform/settlement_not_vip_result HTTP/1.1" 500 145
[2020-08-10 17:45:46,196] [basehttp.py:157] [basehttp:log_message] [INFO]- "GET /platform/settlement_vip HTTP/1.1" 200 3471
[2020-08-10 17:45:47,678] [log.py:228] [log:log_response] [ERROR]- Internal Server Error: /platform/settlement_vip_result
Traceback (most recent call last):
  File "C:\Users\dell\AppData\Local\Programs\Python\Python37\lib\site-packages\django\db\backends\utils.py", line 86, in _execute
    return self.cursor.execute(sql, params)
  File "C:\Users\dell\AppData\Local\Programs\Python\Python37\lib\site-packages\django\db\backends\mysql\base.py", line 74, in execute
    return self.cursor.execute(query, args)
  File "C:\Users\dell\AppData\Local\Programs\Python\Python37\lib\site-packages\pymysql\cursors.py", line 163, in execute
    result = self._query(query)
  File "C:\Users\dell\AppData\Local\Programs\Python\Python37\lib\site-packages\pymysql\cursors.py", line 321, in _query
    conn.query(q)
  File "C:\Users\dell\AppData\Local\Programs\Python\Python37\lib\site-packages\pymysql\connections.py", line 505, in query
    self._affected_rows = self._read_query_result(unbuffered=unbuffered)
  File "C:\Users\dell\AppData\Local\Programs\Python\Python37\lib\site-packages\pymysql\connections.py", line 724, in _read_query_result
    result.read()
  File "C:\Users\dell\AppData\Local\Programs\Python\Python37\lib\site-packages\pymysql\connections.py", line 1069, in read
    first_packet = self.connection._read_packet()
  File "C:\Users\dell\AppData\Local\Programs\Python\Python37\lib\site-packages\pymysql\connections.py", line 676, in _read_packet
    packet.raise_for_error()
  File "C:\Users\dell\AppData\Local\Programs\Python\Python37\lib\site-packages\pymysql\protocol.py", line 223, in raise_for_error
    err.raise_mysql_exception(self._data)
  File "C:\Users\dell\AppData\Local\Programs\Python\Python37\lib\site-packages\pymysql\err.py", line 107, in raise_mysql_exception
    raise errorclass(errno, errval)
pymysql.err.ProgrammingError: (1146, "Table 'autotest.login_settlement_vip_models' doesn't exist")

The above exception was the direct cause of the following exception:

Traceback (most recent call last):
  File "C:\Users\dell\AppData\Local\Programs\Python\Python37\lib\site-packages\django\core\handlers\exception.py", line 34, in inner
    response = get_response(request)
  File "C:\Users\dell\AppData\Local\Programs\Python\Python37\lib\site-packages\django\core\handlers\base.py", line 115, in _get_response
    response = self.process_exception_by_middleware(e, request)
  File "C:\Users\dell\AppData\Local\Programs\Python\Python37\lib\site-packages\django\core\handlers\base.py", line 113, in _get_response
    response = wrapped_callback(request, *callback_args, **callback_kwargs)
  File "E:\Auto\testplat\login\viewas\platform_views\settlement_vip_views.py", line 55, in settlement_vip_result
    print('结算结果：', settlement_data)
  File "C:\Users\dell\AppData\Local\Programs\Python\Python37\lib\site-packages\django\db\models\query.py", line 252, in __repr__
    data = list(self[:REPR_OUTPUT_SIZE + 1])
  File "C:\Users\dell\AppData\Local\Programs\Python\Python37\lib\site-packages\django\db\models\query.py", line 276, in __iter__
    self._fetch_all()
  File "C:\Users\dell\AppData\Local\Programs\Python\Python37\lib\site-packages\django\db\models\query.py", line 1261, in _fetch_all
    self._result_cache = list(self._iterable_class(self))
  File "C:\Users\dell\AppData\Local\Programs\Python\Python37\lib\site-packages\django\db\models\query.py", line 115, in __iter__
    for row in compiler.results_iter(chunked_fetch=self.chunked_fetch, chunk_size=self.chunk_size):
  File "C:\Users\dell\AppData\Local\Programs\Python\Python37\lib\site-packages\django\db\models\sql\compiler.py", line 1104, in results_iter
    results = self.execute_sql(MULTI, chunked_fetch=chunked_fetch, chunk_size=chunk_size)
  File "C:\Users\dell\AppData\Local\Programs\Python\Python37\lib\site-packages\django\db\models\sql\compiler.py", line 1152, in execute_sql
    cursor.execute(sql, params)
  File "C:\Users\dell\AppData\Local\Programs\Python\Python37\lib\site-packages\django\db\backends\utils.py", line 68, in execute
    return self._execute_with_wrappers(sql, params, many=False, executor=self._execute)
  File "C:\Users\dell\AppData\Local\Programs\Python\Python37\lib\site-packages\django\db\backends\utils.py", line 77, in _execute_with_wrappers
    return executor(sql, params, many, context)
  File "C:\Users\dell\AppData\Local\Programs\Python\Python37\lib\site-packages\django\db\backends\utils.py", line 86, in _execute
    return self.cursor.execute(sql, params)
  File "C:\Users\dell\AppData\Local\Programs\Python\Python37\lib\site-packages\django\db\utils.py", line 90, in __exit__
    raise dj_exc_value.with_traceback(traceback) from exc_value
  File "C:\Users\dell\AppData\Local\Programs\Python\Python37\lib\site-packages\django\db\backends\utils.py", line 86, in _execute
    return self.cursor.execute(sql, params)
  File "C:\Users\dell\AppData\Local\Programs\Python\Python37\lib\site-packages\django\db\backends\mysql\base.py", line 74, in execute
    return self.cursor.execute(query, args)
  File "C:\Users\dell\AppData\Local\Programs\Python\Python37\lib\site-packages\pymysql\cursors.py", line 163, in execute
    result = self._query(query)
  File "C:\Users\dell\AppData\Local\Programs\Python\Python37\lib\site-packages\pymysql\cursors.py", line 321, in _query
    conn.query(q)
  File "C:\Users\dell\AppData\Local\Programs\Python\Python37\lib\site-packages\pymysql\connections.py", line 505, in query
    self._affected_rows = self._read_query_result(unbuffered=unbuffered)
  File "C:\Users\dell\AppData\Local\Programs\Python\Python37\lib\site-packages\pymysql\connections.py", line 724, in _read_query_result
    result.read()
  File "C:\Users\dell\AppData\Local\Programs\Python\Python37\lib\site-packages\pymysql\connections.py", line 1069, in read
    first_packet = self.connection._read_packet()
  File "C:\Users\dell\AppData\Local\Programs\Python\Python37\lib\site-packages\pymysql\connections.py", line 676, in _read_packet
    packet.raise_for_error()
  File "C:\Users\dell\AppData\Local\Programs\Python\Python37\lib\site-packages\pymysql\protocol.py", line 223, in raise_for_error
    err.raise_mysql_exception(self._data)
  File "C:\Users\dell\AppData\Local\Programs\Python\Python37\lib\site-packages\pymysql\err.py", line 107, in raise_mysql_exception
    raise errorclass(errno, errval)
django.db.utils.ProgrammingError: (1146, "Table 'autotest.login_settlement_vip_models' doesn't exist")
[2020-08-10 17:45:47,680] [basehttp.py:157] [basehttp:log_message] [ERROR]- "GET /platform/settlement_vip_result HTTP/1.1" 500 145
[2020-08-10 17:45:51,839] [log.py:228] [log:log_response] [ERROR]- Internal Server Error: /platform/settlement_vip_result
Traceback (most recent call last):
  File "C:\Users\dell\AppData\Local\Programs\Python\Python37\lib\site-packages\django\db\backends\utils.py", line 86, in _execute
    return self.cursor.execute(sql, params)
  File "C:\Users\dell\AppData\Local\Programs\Python\Python37\lib\site-packages\django\db\backends\mysql\base.py", line 74, in execute
    return self.cursor.execute(query, args)
  File "C:\Users\dell\AppData\Local\Programs\Python\Python37\lib\site-packages\pymysql\cursors.py", line 163, in execute
    result = self._query(query)
  File "C:\Users\dell\AppData\Local\Programs\Python\Python37\lib\site-packages\pymysql\cursors.py", line 321, in _query
    conn.query(q)
  File "C:\Users\dell\AppData\Local\Programs\Python\Python37\lib\site-packages\pymysql\connections.py", line 505, in query
    self._affected_rows = self._read_query_result(unbuffered=unbuffered)
  File "C:\Users\dell\AppData\Local\Programs\Python\Python37\lib\site-packages\pymysql\connections.py", line 724, in _read_query_result
    result.read()
  File "C:\Users\dell\AppData\Local\Programs\Python\Python37\lib\site-packages\pymysql\connections.py", line 1069, in read
    first_packet = self.connection._read_packet()
  File "C:\Users\dell\AppData\Local\Programs\Python\Python37\lib\site-packages\pymysql\connections.py", line 676, in _read_packet
    packet.raise_for_error()
  File "C:\Users\dell\AppData\Local\Programs\Python\Python37\lib\site-packages\pymysql\protocol.py", line 223, in raise_for_error
    err.raise_mysql_exception(self._data)
  File "C:\Users\dell\AppData\Local\Programs\Python\Python37\lib\site-packages\pymysql\err.py", line 107, in raise_mysql_exception
    raise errorclass(errno, errval)
pymysql.err.ProgrammingError: (1146, "Table 'autotest.login_settlement_vip_models' doesn't exist")

The above exception was the direct cause of the following exception:

Traceback (most recent call last):
  File "C:\Users\dell\AppData\Local\Programs\Python\Python37\lib\site-packages\django\core\handlers\exception.py", line 34, in inner
    response = get_response(request)
  File "C:\Users\dell\AppData\Local\Programs\Python\Python37\lib\site-packages\django\core\handlers\base.py", line 115, in _get_response
    response = self.process_exception_by_middleware(e, request)
  File "C:\Users\dell\AppData\Local\Programs\Python\Python37\lib\site-packages\django\core\handlers\base.py", line 113, in _get_response
    response = wrapped_callback(request, *callback_args, **callback_kwargs)
  File "E:\Auto\testplat\login\viewas\platform_views\settlement_vip_views.py", line 55, in settlement_vip_result
    print('结算结果：', settlement_data)
  File "C:\Users\dell\AppData\Local\Programs\Python\Python37\lib\site-packages\django\db\models\query.py", line 252, in __repr__
    data = list(self[:REPR_OUTPUT_SIZE + 1])
  File "C:\Users\dell\AppData\Local\Programs\Python\Python37\lib\site-packages\django\db\models\query.py", line 276, in __iter__
    self._fetch_all()
  File "C:\Users\dell\AppData\Local\Programs\Python\Python37\lib\site-packages\django\db\models\query.py", line 1261, in _fetch_all
    self._result_cache = list(self._iterable_class(self))
  File "C:\Users\dell\AppData\Local\Programs\Python\Python37\lib\site-packages\django\db\models\query.py", line 115, in __iter__
    for row in compiler.results_iter(chunked_fetch=self.chunked_fetch, chunk_size=self.chunk_size):
  File "C:\Users\dell\AppData\Local\Programs\Python\Python37\lib\site-packages\django\db\models\sql\compiler.py", line 1104, in results_iter
    results = self.execute_sql(MULTI, chunked_fetch=chunked_fetch, chunk_size=chunk_size)
  File "C:\Users\dell\AppData\Local\Programs\Python\Python37\lib\site-packages\django\db\models\sql\compiler.py", line 1152, in execute_sql
    cursor.execute(sql, params)
  File "C:\Users\dell\AppData\Local\Programs\Python\Python37\lib\site-packages\django\db\backends\utils.py", line 68, in execute
    return self._execute_with_wrappers(sql, params, many=False, executor=self._execute)
  File "C:\Users\dell\AppData\Local\Programs\Python\Python37\lib\site-packages\django\db\backends\utils.py", line 77, in _execute_with_wrappers
    return executor(sql, params, many, context)
  File "C:\Users\dell\AppData\Local\Programs\Python\Python37\lib\site-packages\django\db\backends\utils.py", line 86, in _execute
    return self.cursor.execute(sql, params)
  File "C:\Users\dell\AppData\Local\Programs\Python\Python37\lib\site-packages\django\db\utils.py", line 90, in __exit__
    raise dj_exc_value.with_traceback(traceback) from exc_value
  File "C:\Users\dell\AppData\Local\Programs\Python\Python37\lib\site-packages\django\db\backends\utils.py", line 86, in _execute
    return self.cursor.execute(sql, params)
  File "C:\Users\dell\AppData\Local\Programs\Python\Python37\lib\site-packages\django\db\backends\mysql\base.py", line 74, in execute
    return self.cursor.execute(query, args)
  File "C:\Users\dell\AppData\Local\Programs\Python\Python37\lib\site-packages\pymysql\cursors.py", line 163, in execute
    result = self._query(query)
  File "C:\Users\dell\AppData\Local\Programs\Python\Python37\lib\site-packages\pymysql\cursors.py", line 321, in _query
    conn.query(q)
  File "C:\Users\dell\AppData\Local\Programs\Python\Python37\lib\site-packages\pymysql\connections.py", line 505, in query
    self._affected_rows = self._read_query_result(unbuffered=unbuffered)
  File "C:\Users\dell\AppData\Local\Programs\Python\Python37\lib\site-packages\pymysql\connections.py", line 724, in _read_query_result
    result.read()
  File "C:\Users\dell\AppData\Local\Programs\Python\Python37\lib\site-packages\pymysql\connections.py", line 1069, in read
    first_packet = self.connection._read_packet()
  File "C:\Users\dell\AppData\Local\Programs\Python\Python37\lib\site-packages\pymysql\connections.py", line 676, in _read_packet
    packet.raise_for_error()
  File "C:\Users\dell\AppData\Local\Programs\Python\Python37\lib\site-packages\pymysql\protocol.py", line 223, in raise_for_error
    err.raise_mysql_exception(self._data)
  File "C:\Users\dell\AppData\Local\Programs\Python\Python37\lib\site-packages\pymysql\err.py", line 107, in raise_mysql_exception
    raise errorclass(errno, errval)
django.db.utils.ProgrammingError: (1146, "Table 'autotest.login_settlement_vip_models' doesn't exist")
[2020-08-10 17:45:51,841] [basehttp.py:157] [basehttp:log_message] [ERROR]- "GET /platform/settlement_vip_result HTTP/1.1" 500 145
[2020-08-10 17:50:32,392] [autoreload.py:598] [autoreload:run_with_reloader] [INFO]- Watching for file changes with StatReloader
[2020-08-10 17:50:36,459] [basehttp.py:157] [basehttp:log_message] [INFO]- "GET /run_test/ HTTP/1.1" 200 3285
[2020-08-10 17:51:32,838] [autotest_view.py:103] [autotest_view:run_test] [INFO]- 测试完成！ 测试结果集合为:{'filename': 'test_report20200810175040', 'result': {'testAll': 47, 'testPass': 39, 'testFail': 8, 'testError': 0}}
[2020-08-10 17:51:35,266] [basehttp.py:157] [basehttp:log_message] [INFO]- "GET /run_test/?csrfmiddlewaretoken=MC32l6P7yZHb47Qtc54AH4fAl9rVlJVbn5Il1cURKSRlqLFPawP375s1LvQT66hd&test_type=All&envId=3&project=platform-billing-admin HTTP/1.1" 200 106
[2020-08-10 17:52:07,023] [basehttp.py:157] [basehttp:log_message] [INFO]- "GET /test_report_list10/ HTTP/1.1" 200 13663
[2020-08-10 17:52:07,483] [basehttp.py:157] [basehttp:log_message] [INFO]- "GET /api/echarts/ HTTP/1.1" 200 905
[2020-08-10 17:52:07,513] [basehttp.py:157] [basehttp:log_message] [INFO]- "GET /api/pass_stats/ HTTP/1.1" 200 4646
[2020-08-10 17:52:21,773] [basehttp.py:157] [basehttp:log_message] [INFO]- "GET /test_report/test_report20200810175040 HTTP/1.1" 200 17428132
[2020-08-10 17:55:19,828] [autoreload.py:222] [autoreload:trigger_reload] [INFO]- E:\Auto\testplat\login\testcases\case_new\admin\case_Platform_PartnerList.py changed, reloading.
[2020-08-10 17:55:20,926] [autoreload.py:598] [autoreload:run_with_reloader] [INFO]- Watching for file changes with StatReloader
[2020-08-10 17:56:36,247] [autoreload.py:222] [autoreload:trigger_reload] [INFO]- E:\Auto\testplat\MyPro1\settings.py changed, reloading.
[2020-08-10 17:56:37,358] [autoreload.py:598] [autoreload:run_with_reloader] [INFO]- Watching for file changes with StatReloader
[2020-08-12 14:54:00,464] [autoreload.py:222] [autoreload:trigger_reload] [INFO]- E:\Auto\testplat\login\templates\admin\platform\settlement\Settlement.py changed, reloading.
