[2020-07-09 16:19:23,184] [basehttp.py:124] [basehttp:log_message] [INFO]- "GET /index/ HTTP/1.1" 200 10132
[2020-07-09 16:19:26,691] [basehttp.py:124] [basehttp:log_message] [INFO]- "GET /run_test/ HTTP/1.1" 200 3064
[2020-07-09 16:20:45,632] [basehttp.py:124] [basehttp:log_message] [INFO]- "GET /run_test/ HTTP/1.1" 200 3119
[2020-07-09 16:22:54,832] [basehttp.py:124] [basehttp:log_message] [INFO]- "GET /run_test/ HTTP/1.1" 200 3119
[2020-07-09 16:28:08,979] [basehttp.py:124] [basehttp:log_message] [INFO]- "GET /index/ HTTP/1.1" 200 10132
[2020-07-09 16:28:13,635] [basehttp.py:124] [basehttp:log_message] [INFO]- "GET /test_report_list10/ HTTP/1.1" 200 10313
[2020-07-09 16:28:16,816] [basehttp.py:124] [basehttp:log_message] [INFO]- "GET /api/echarts/ HTTP/1.1" 200 60
[2020-07-09 16:33:05,836] [basehttp.py:124] [basehttp:log_message] [INFO]- "GET /run_test/ HTTP/1.1" 200 3119
[2020-07-09 16:37:25,861] [basehttp.py:124] [basehttp:log_message] [INFO]- "GET /run_test/ HTTP/1.1" 200 3119
[2020-07-09 16:38:42,282] [exception.py:118] [exception:handle_uncaught_exception] [ERROR]- Internal Server Error: /run_test/
Traceback (most recent call last):
  File "D:\Programs\Python\Python37\Lib\site-packages\urllib3\connectionpool.py", line 595, in urlopen
    self._prepare_proxy(conn)
  File "D:\Programs\Python\Python37\Lib\site-packages\urllib3\connectionpool.py", line 816, in _prepare_proxy
    conn.connect()
  File "D:\Programs\Python\Python37\Lib\site-packages\urllib3\connection.py", line 326, in connect
    ssl_context=context)
  File "D:\Programs\Python\Python37\Lib\site-packages\urllib3\util\ssl_.py", line 329, in ssl_wrap_socket
    return context.wrap_socket(sock, server_hostname=server_hostname)
  File "D:\Programs\Python\Python37\lib\ssl.py", line 412, in wrap_socket
    session=session
  File "D:\Programs\Python\Python37\lib\ssl.py", line 853, in _create
    self.do_handshake()
  File "D:\Programs\Python\Python37\lib\ssl.py", line 1117, in do_handshake
    self._sslobj.do_handshake()
ssl.SSLCertVerificationError: [SSL: CERTIFICATE_VERIFY_FAILED] certificate verify failed: unable to get local issuer certificate (_ssl.c:1056)

During handling of the above exception, another exception occurred:

Traceback (most recent call last):
  File "D:\Programs\Python\Python37\Lib\site-packages\requests\adapters.py", line 440, in send
    timeout=timeout
  File "D:\Programs\Python\Python37\Lib\site-packages\urllib3\connectionpool.py", line 639, in urlopen
    _stacktrace=sys.exc_info()[2])
  File "D:\Programs\Python\Python37\Lib\site-packages\urllib3\util\retry.py", line 388, in increment
    raise MaxRetryError(_pool, url, error or ResponseError(cause))
urllib3.exceptions.MaxRetryError: HTTPSConnectionPool(host='qyapi.weixin.qq.com', port=443): Max retries exceeded with url: /cgi-bin/webhook/send?key=15cdf3d2-80fd-4c1c-b648-33f500ab73ef (Caused by SSLError(SSLCertVerificationError(1, '[SSL: CERTIFICATE_VERIFY_FAILED] certificate verify failed: unable to get local issuer certificate (_ssl.c:1056)')))

During handling of the above exception, another exception occurred:

Traceback (most recent call last):
  File "D:\Programs\Python\Python37\Lib\site-packages\django\core\handlers\exception.py", line 35, in inner
    response = get_response(request)
  File "D:\Programs\Python\Python37\Lib\site-packages\django\core\handlers\base.py", line 128, in _get_response
    response = self.process_exception_by_middleware(e, request)
  File "D:\Programs\Python\Python37\Lib\site-packages\django\core\handlers\base.py", line 126, in _get_response
    response = wrapped_callback(request, *callback_args, **callback_kwargs)
  File "D:\Programs\Python\Python37\Lib\site-packages\django\views\decorators\csrf.py", line 54, in wrapped_view
    return view_func(*args, **kwargs)
  File "D:\PycharmProjects\MyPro1\login\viewas\test_view\autotest_view.py", line 152, in run_test
    msg_robot(message, robotKey)
  File "D:\PycharmProjects\MyPro1\login\templates\utils\wechat_robot.py", line 34, in msg_robot
    json=data
  File "D:\Programs\Python\Python37\Lib\site-packages\requests\api.py", line 112, in post
    return request('post', url, data=data, json=json, **kwargs)
  File "D:\Programs\Python\Python37\Lib\site-packages\requests\api.py", line 58, in request
    return session.request(method=method, url=url, **kwargs)
  File "D:\Programs\Python\Python37\Lib\site-packages\requests\sessions.py", line 508, in request
    resp = self.send(prep, **send_kwargs)
  File "D:\Programs\Python\Python37\Lib\site-packages\requests\sessions.py", line 618, in send
    r = adapter.send(request, **kwargs)
  File "D:\Programs\Python\Python37\Lib\site-packages\requests\adapters.py", line 506, in send
    raise SSLError(e, request=request)
requests.exceptions.SSLError: HTTPSConnectionPool(host='qyapi.weixin.qq.com', port=443): Max retries exceeded with url: /cgi-bin/webhook/send?key=15cdf3d2-80fd-4c1c-b648-33f500ab73ef (Caused by SSLError(SSLCertVerificationError(1, '[SSL: CERTIFICATE_VERIFY_FAILED] certificate verify failed: unable to get local issuer certificate (_ssl.c:1056)')))
[2020-07-09 16:38:42,515] [basehttp.py:124] [basehttp:log_message] [ERROR]- "GET /run_test/?csrfmiddlewaretoken=NfcYgUYvUQA4HisamXw93zHrt1k4inezozBI9Bd54Ow9muRIhUPMnkzOCef6Wynf&test_type=AdminNec&envId=4&project=yyting-apps-admin HTTP/1.1" 500 179446
[2020-07-09 16:39:24,536] [basehttp.py:124] [basehttp:log_message] [INFO]- "GET /run_test/?csrfmiddlewaretoken=NfcYgUYvUQA4HisamXw93zHrt1k4inezozBI9Bd54Ow9muRIhUPMnkzOCef6Wynf&test_type=AdminNec&envId=4&project=yyting-apps-admin HTTP/1.1" 200 91
[2020-07-09 16:54:03,437] [basehttp.py:124] [basehttp:log_message] [INFO]- "GET /run_test/?csrfmiddlewaretoken=NfcYgUYvUQA4HisamXw93zHrt1k4inezozBI9Bd54Ow9muRIhUPMnkzOCef6Wynf&test_type=AdminNec&envId=3&project=yyting-apps-admin HTTP/1.1" 200 91
[2020-07-09 16:54:30,955] [basehttp.py:124] [basehttp:log_message] [INFO]- "GET /run_test/?csrfmiddlewaretoken=NfcYgUYvUQA4HisamXw93zHrt1k4inezozBI9Bd54Ow9muRIhUPMnkzOCef6Wynf&test_type=AdminNec&envId=3&project=yyting-apps-admin HTTP/1.1" 200 91
[2020-07-09 16:55:04,545] [basehttp.py:124] [basehttp:log_message] [INFO]- "GET /test_report_list10/ HTTP/1.1" 200 11249
[2020-07-09 16:55:06,705] [basehttp.py:124] [basehttp:log_message] [INFO]- "GET /api/echarts/ HTTP/1.1" 200 80
[2020-07-09 16:55:32,565] [basehttp.py:124] [basehttp:log_message] [INFO]- "GET /test_report_list10/ HTTP/1.1" 200 11249
[2020-07-09 16:55:34,686] [basehttp.py:124] [basehttp:log_message] [INFO]- "GET /api/echarts/ HTTP/1.1" 200 80
[2020-07-09 16:57:01,700] [basehttp.py:124] [basehttp:log_message] [INFO]- "GET /test_report_list10/ HTTP/1.1" 200 11304
[2020-07-09 16:57:03,791] [basehttp.py:124] [basehttp:log_message] [INFO]- "GET /api/echarts/ HTTP/1.1" 200 80
[2020-07-09 17:39:19,614] [basehttp.py:124] [basehttp:log_message] [INFO]- "GET /index/ HTTP/1.1" 200 9923
[2020-07-09 17:39:25,065] [base.py:93] [base:get_response] [WARNING]- Not Found: /
[2020-07-09 17:39:25,067] [basehttp.py:124] [basehttp:log_message] [WARNING]- "GET / HTTP/1.1" 404 6305
[2020-07-09 17:39:36,744] [basehttp.py:124] [basehttp:log_message] [INFO]- "GET /add_copyright_partner/ HTTP/1.1" 200 3033
[2020-07-09 17:40:10,524] [exception.py:118] [exception:handle_uncaught_exception] [ERROR]- Internal Server Error: /add_copyright_partner/
Traceback (most recent call last):
  File "D:\Programs\Python\Python37\Lib\site-packages\django\core\handlers\exception.py", line 35, in inner
    response = get_response(request)
  File "D:\Programs\Python\Python37\Lib\site-packages\django\core\handlers\base.py", line 128, in _get_response
    response = self.process_exception_by_middleware(e, request)
  File "D:\Programs\Python\Python37\Lib\site-packages\django\core\handlers\base.py", line 126, in _get_response
    response = wrapped_callback(request, *callback_args, **callback_kwargs)
  File "D:\PycharmProjects\MyPro1\login\viewas\platform_views\copyright_views.py", line 23, in add_copyright_partner
    result = add_CopyrightPartner(copyright_type)
  File "D:\PycharmProjects\MyPro1\login\templates\admin\platform\add_Partner\Add_CopyrightPartner.py", line 99, in add_CopyrightPartner
    data['id'] = ''
UnboundLocalError: local variable 'data' referenced before assignment
[2020-07-09 17:40:10,665] [basehttp.py:124] [basehttp:log_message] [ERROR]- "POST /add_copyright_partner/ HTTP/1.1" 500 78824
[2020-07-09 17:41:10,713] [exception.py:118] [exception:handle_uncaught_exception] [ERROR]- Internal Server Error: /add_copyright_partner/
Traceback (most recent call last):
  File "D:\Programs\Python\Python37\Lib\site-packages\django\core\handlers\exception.py", line 35, in inner
    response = get_response(request)
  File "D:\Programs\Python\Python37\Lib\site-packages\django\core\handlers\base.py", line 128, in _get_response
    response = self.process_exception_by_middleware(e, request)
  File "D:\Programs\Python\Python37\Lib\site-packages\django\core\handlers\base.py", line 126, in _get_response
    response = wrapped_callback(request, *callback_args, **callback_kwargs)
  File "D:\PycharmProjects\MyPro1\login\viewas\platform_views\copyright_views.py", line 23, in add_copyright_partner
    result = add_CopyrightPartner(copyright_type)
  File "D:\PycharmProjects\MyPro1\login\templates\admin\platform\add_Partner\Add_CopyrightPartner.py", line 99, in add_CopyrightPartner
    data['id'] = ''
UnboundLocalError: local variable 'data' referenced before assignment
[2020-07-09 17:41:10,742] [basehttp.py:124] [basehttp:log_message] [ERROR]- "POST /add_copyright_partner/ HTTP/1.1" 500 78825
[2020-07-09 17:43:34,956] [exception.py:118] [exception:handle_uncaught_exception] [ERROR]- Internal Server Error: /add_copyright_partner/
Traceback (most recent call last):
  File "D:\Programs\Python\Python37\Lib\site-packages\django\core\handlers\exception.py", line 35, in inner
    response = get_response(request)
  File "D:\Programs\Python\Python37\Lib\site-packages\django\core\handlers\base.py", line 128, in _get_response
    response = self.process_exception_by_middleware(e, request)
  File "D:\Programs\Python\Python37\Lib\site-packages\django\core\handlers\base.py", line 126, in _get_response
    response = wrapped_callback(request, *callback_args, **callback_kwargs)
  File "D:\PycharmProjects\MyPro1\login\viewas\platform_views\copyright_views.py", line 24, in add_copyright_partner
    result = add_CopyrightPartner(copyright_type)
  File "D:\PycharmProjects\MyPro1\login\templates\admin\platform\add_Partner\Add_CopyrightPartner.py", line 99, in add_CopyrightPartner
    data['id'] = ''
UnboundLocalError: local variable 'data' referenced before assignment
[2020-07-09 17:43:35,086] [basehttp.py:124] [basehttp:log_message] [ERROR]- "POST /add_copyright_partner/ HTTP/1.1" 500 78849
[2020-07-09 17:44:07,728] [basehttp.py:124] [basehttp:log_message] [INFO]- "POST /add_copyright_partner/ HTTP/1.1" 200 3194
[2020-07-09 17:47:17,753] [basehttp.py:124] [basehttp:log_message] [INFO]- "GET /index/ HTTP/1.1" 200 9943
[2020-07-09 17:47:19,985] [basehttp.py:124] [basehttp:log_message] [INFO]- "GET /index/ HTTP/1.1" 200 9943
[2020-07-09 17:47:38,641] [basehttp.py:124] [basehttp:log_message] [INFO]- "GET /index/ HTTP/1.1" 200 9943
[2020-07-09 18:05:06,713] [basehttp.py:124] [basehttp:log_message] [INFO]- "GET /add_copyright_partner/ HTTP/1.1" 200 3033
[2020-07-09 18:26:43,352] [basehttp.py:124] [basehttp:log_message] [INFO]- "GET /index/ HTTP/1.1" 200 9943
[2020-07-09 18:26:46,148] [basehttp.py:124] [basehttp:log_message] [INFO]- "GET /add_copyright_partner/ HTTP/1.1" 200 3033
[2020-07-09 18:26:59,924] [basehttp.py:124] [basehttp:log_message] [INFO]- "GET /add_copyright_partner/ HTTP/1.1" 200 3033
[2020-07-09 18:27:01,641] [basehttp.py:124] [basehttp:log_message] [INFO]- "GET /add_copyright_partner/ HTTP/1.1" 200 3033
[2020-07-10 09:50:24,629] [basehttp.py:124] [basehttp:log_message] [INFO]- "GET /index/ HTTP/1.1" 200 9943
[2020-07-10 09:50:28,436] [basehttp.py:124] [basehttp:log_message] [INFO]- "GET /add_copyright_partner/ HTTP/1.1" 200 3033
[2020-07-10 09:50:36,348] [basehttp.py:124] [basehttp:log_message] [INFO]- "GET /index/ HTTP/1.1" 200 9943
